Workbook

Sheet CLASS TT
A1: L J Institute of Engineering and Technology
A2: FY1 SEM I 2025 (CE/AIML)
A3: Class Time Table Effective From 09TH SEPT 2025
C4: BRANCH | D4: CE/AIML
A5: DAY | B5: LECTURE NO | C5: DIVISION | D5: D-1 | H5: D-2 | L5: D-3 | P5: D-4 | T5: D-5 | X5: D-6 | AB5: D-7 | AF5: D-8 | AJ5: D-9 | AN5: C-10 | AR5: A-11
C6: TIME/ ROOM NO. | D6: BATCH-1 | H6: BATCH-2 | L6: BATCH-3 | P6: BATCH-4 | T6: BATCH-5 | X6: BATCH-6 | AB6: BATCH-7 | AF6: BATCH-8 | AJ6: BATCH-9 | AN6: BATCH-10 | AR6: BATCH-11 | AV6: BATCH-12 | AZ6: BATCH-13
D7: Subject | E7: Batch | F7: Faculty | G7: Room No | H7: Subject | I7: Batch | J7: Faculty | K7: Room No | L7: Subject | M7: Batch | N7: Faculty | O7: Room No | P7: Subject | Q7: Batch | R7: Faculty | S7: Room No | T7: Subject | U7: Batch | V7: Faculty | W7: Room No | X7: Subject | Y7: Batch | Z7: Faculty | AA7: Room No | AB7: Subject | AC7: Batch | AD7: Faculty | AE7: Room No | AF7: Subject | AG7: Batch | AH7: Faculty | AI7: Room No | AJ7: Subject | AK7: Batch | AL7: Faculty | AM7: Room No | AN7: Subject | AO7: Batch | AP7: Faculty | AQ7: Room No | AR7: Subject | AS7: Batch | AT7: Faculty | AU7: Room No | AV7: Subject | AW7: Batch | AX7: Faculty | AY7: Room No | AZ7: Subject | BA7: Batch | BB7: Faculty | BC7: Room No
A8: MON | B8: 1 | C8: 8:45am to 9:45am | D8: =TT!D8 -> ES | E8: =TT!E8 -> 0 | F8: =TT!F8 -> NND | G8: =TT!G8 -> 501 | H8: =TT!H8 -> ES | I8: =TT!I8 -> 0 | J8: =TT!J8 -> NND | K8: =TT!K8 -> 501 | ... BC8: =TT!BC8 -> 0
D9: =TT!D9 -> 0 | E9: =TT!E9 -> 0 | F9: =TT!F9 -> 0 | G9: =TT!G9 -> 0 | H9: =TT!H9 -> 0 | I9: =TT!I9 -> 0 | J9: =TT!J9 -> 0 | K9: =TT!K9 -> 0 | ... BC9: =TT!BC9 -> 0
B10: 2 | C10: 9:45 am to 10:45 am | D10: =TT!D10 -> MATHS-I | E10: =TT!E10 -> 0 | F10: =TT!F10 -> AMS | G10: =TT!G10 -> 501 | H10: =TT!H10 -> PHY | I10: =TT!I10 -> 0 | J10: =TT!J10 -> PYR | K10: =TT!K10 -> 509 | ... BC10: =TT!BC10 -> 0
D11: =TT!D11 -> 0 | E11: =TT!E11 -> 0 | F11: =TT!F11 -> 0 | G11: =TT!G11 -> 0 | H11: =TT!H11 -> 0 | I11: =TT!I11 -> 0 | J11: =TT!J11 -> 0 | K11: =TT!K11 -> 0 | ... BC11: =TT!BC11 -> 0
B12: BREAK | C12: 10:45 am to 11:30 am | D12: =TT!D12 -> 0 | E12: =TT!E12 -> 0 | F12: =TT!F12 -> 0 | G12: =TT!G12 -> 0 | H12: =TT!H12 -> 0 | I12: =TT!I12 -> 0 | J12: =TT!J12 -> 0 | K12: =TT!K12 -> 0 | ... BC12: =TT!BC12 -> 0
D13: =TT!D13 -> 0 | E13: =TT!E13 -> 0 | F13: =TT!F13 -> 0 | G13: =TT!G13 -> 0 | H13: =TT!H13 -> 0 | I13: =TT!I13 -> 0 | J13: =TT!J13 -> 0 | K13: =TT!K13 -> 0 | ... BC13: =TT!BC13 -> 0
B14: 3 | C14: 11:30am to 12:30pm | D14: =TT!D14 -> SE | E14: =TT!E14 -> 0 | F14: =TT!F14 -> IRS | G14: =TT!G14 -> 506-A | H14: =TT!H14 -> PYTHON-I | I14: =TT!I14 -> 0 | J14: =TT!J14 -> MDP | K14: =TT!K14 -> 506-D | ... BC14: =TT!BC14 -> 0
D15: =TT!D15 -> 0 | E15: =TT!E15 -> 0 | F15: =TT!F15 -> 0 | G15: =TT!G15 -> 0 | H15: =TT!H15 -> 0 | I15: =TT!I15 -> 0 | J15: =TT!J15 -> 0 | K15: =TT!K15 -> 0 | ... BC15: =TT!BC15 -> 0
B16: 4 | C16: 12:30pm to 1:30pm | D16: =TT!D16 -> PHY | E16: =TT!E16 -> 0 | F16: =TT!F16 -> KGB | G16: =TT!G16 -> 506-A | H16: =TT!H16 -> PYTHON-I | I16: =TT!I16 -> 0 | J16: =TT!J16 -> MDP | K16: =TT!K16 -> 506-D | ... BC16: =TT!BC16 -> 0
D17: =TT!D17 -> 0 | E17: =TT!E17 -> 0 | F17: =TT!F17 -> 0 | G17: =TT!G17 -> 0 | H17: =TT!H17 -> 0 | I17: =TT!I17 -> 0 | J17: =TT!J17 -> 0 | K17: =TT!K17 -> 0 | ... BC17: =TT!BC17 -> 0
B18: 5 | C18: 1:30pm to 2:30pm | D18: =TT!D18 -> 0 | E18: =TT!E18 -> 0 | F18: =TT!F18 -> 0 | G18: =TT!G18 -> 0 | H18: =TT!H18 -> 0 | I18: =TT!I18 -> 0 | J18: =TT!J18 -> 0 | K18: =TT!K18 -> 0 | ... BC18: =TT!BC18 -> 0
D19: =TT!D19 -> 0 | E19: =TT!E19 -> 0 | F19: =TT!F19 -> 0 | G19: =TT!G19 -> 0 | H19: =TT!H19 -> 0 | I19: =TT!I19 -> 0 | J19: =TT!J19 -> 0 | K19: =TT!K19 -> 0 | ... BC19: =TT!BC19 -> 0
D20: =TT!D20 -> 0 | E20: =TT!E20 -> 0 | F20: =TT!F20 -> 0 | G20: =TT!G20 -> 0 | H20: =TT!H20 -> 0 | I20: =TT!I20 -> 0 | J20: =TT!J20 -> 0 | K20: =TT!K20 -> 0 | ... BC20: =TT!BC20 -> 0
A21: TUE | B21: 1 | C21: 8:45am to 9:45am | D21: =TT!D21 -> PYTHON-I | E21: =TT!E21 -> 0 | F21: =TT!F21 -> HDS | G21: =TT!G21 -> 506-A | H21: =TT!H21 -> PHY | I21: =TT!I21 -> 0 | J21: =TT!J21 -> PYR | K21: =TT!K21 -> 509 | ... BC21: =TT!BC21 -> 0
D22: =TT!D22 -> 0 | E22: =TT!E22 -> 0 | F22: =TT!F22 -> 0 | G22: =TT!G22 -> 0 | H22: =TT!H22 -> 0 | I22: =TT!I22 -> 0 | J22: =TT!J22 -> 0 | K22: =TT!K22 -> 0 | ... BC22: =TT!BC22 -> 0
B23: 2 | C23: 9:45 am to 10:45 am | D23: =TT!D23 -> PYTHON-I | E23: =TT!E23 -> 0 | F23: =TT!F23 -> HDS | G23: =TT!G23 -> 506-A | H23: =TT!H23 -> PHY | I23: =TT!I23 -> 0 | J23: =TT!J23 -> PYR | K23: =TT!K23 -> 509 | ... BC23: =TT!BC23 -> 0
D24: =TT!D24 -> 0 | E24: =TT!E24 -> 0 | F24: =TT!F24 -> 0 | G24: =TT!G24 -> 0 | H24: =TT!H24 -> 0 | I24: =TT!I24 -> 0 | J24: =TT!J24 -> 0 | K24: =TT!K24 -> 0 | ... BC24: =TT!BC24 -> 0
B25: BREAK | C25: 10:45 am to 11:30 am | D25: =TT!D25 -> 0 | E25: =TT!E25 -> 0 | F25: =TT!F25 -> 0 | G25: =TT!G25 -> 0 | H25: =TT!H25 -> 0 | I25: =TT!I25 -> 0 | J25: =TT!J25 -> 0 | K25: =TT!K25 -> 0 | ... BC25: =TT!BC25 -> 0
D26: =TT!D26 -> 0 | E26: =TT!E26 -> 0 | F26: =TT!F26 -> 0 | G26: =TT!G26 -> 0 | H26: =TT!H26 -> 0 | I26: =TT!I26 -> 0 | J26: =TT!J26 -> 0 | K26: =TT!K26 -> 0 | ... BC26: =TT!BC26 -> 0
B27: 3 | C27: 11:30am to 12:30pm | D27: =TT!D27 -> MATHS-I | E27: =TT!E27 -> 0 | F27: =TT!F27 -> AMS | G27: =TT!G27 -> 501 | H27: =TT!H27 -> MATHS-I | I27: =TT!I27 -> 0 | J27: =TT!J27 -> PDB | K27: =TT!K27 -> 502 | ... BC27: =TT!BC27 -> 0
D28: =TT!D28 -> 0 | E28: =TT!E28 -> 0 | F28: =TT!F28 -> 0 | G28: =TT!G28 -> 0 | H28: =TT!H28 -> 0 | I28: =TT!I28 -> 0 | J28: =TT!J28 -> 0 | K28: =TT!K28 -> 0 | ... BC28: =TT!BC28 -> 0
B29: 4 | C29: 12:30pm to 1:30pm | D29: =TT!D29 -> MATHS-I | E29: =TT!E29 -> 0 | F29: =TT!F29 -> AMS | G29: =TT!G29 -> 501 | H29: =TT!H29 -> MATHS-I | I29: =TT!I29 -> 0 | J29: =TT!J29 -> PDB | K29: =TT!K29 -> 502 | ... BC29: =TT!BC29 -> 0
D30: =TT!D30 -> 0 | E30: =TT!E30 -> 0 | F30: =TT!F30 -> 0 | G30: =TT!G30 -> 0 | H30: =TT!H30 -> 0 | I30: =TT!I30 -> 0 | J30: =TT!J30 -> 0 | K30: =TT!K30 -> 0 | ... BC30: =TT!BC30 -> 0
B31: 5 | C31: 1:30pm to 2:30pm | D31: =TT!D31 -> 0 | E31: =TT!E31 -> 0 | F31: =TT!F31 -> 0 | G31: =TT!G31 -> 0 | H31: =TT!H31 -> 0 | I31: =TT!I31 -> 0 | J31: =TT!J31 -> 0 | K31: =TT!K31 -> 0 | ... BC31: =TT!BC31 -> 0
D32: =TT!D32 -> 0 | E32: =TT!E32 -> 0 | F32: =TT!F32 -> 0 | G32: =TT!G32 -> 0 | H32: =TT!H32 -> 0 | I32: =TT!I32 -> 0 | J32: =TT!J32 -> 0 | K32: =TT!K32 -> 0 | ... BC32: =TT!BC32 -> 0
D33: =TT!D33 -> 0 | E33: =TT!E33 -> 0 | F33: =TT!F33 -> 0 | G33: =TT!G33 -> 0 | H33: =TT!H33 -> 0 | I33: =TT!I33 -> 0 | J33: =TT!J33 -> 0 | K33: =TT!K33 -> 0 | ... BC33: =TT!BC33 -> 0
A34: WED | B34: 1 | C34: 8:45am to 9:45am | D34: =TT!D34 -> MATHS-I | E34: =TT!E34 -> 0 | F34: =TT!F34 -> AMS | G34: =TT!G34 -> 501 | H34: =TT!H34 -> SE | I34: =TT!I34 -> 0 | J34: =TT!J34 -> IRS | K34: =TT!K34 -> 502 | ... BC34: =TT!BC34 -> 0
D35: =TT!D35 -> 0 | E35: =TT!E35 -> 0 | F35: =TT!F35 -> 0 | G35: =TT!G35 -> 0 | H35: =TT!H35 -> 0 | I35: =TT!I35 -> 0 | J35: =TT!J35 -> 0 | K35: =TT!K35 -> 0 | ... BC35: =TT!BC35 -> 0
B36: 2 | C36: 9:45 am to 10:45 am | D36: =TT!D36 -> MATHS-I | E36: =TT!E36 -> 0 | F36: =TT!F36 -> AMS | G36: =TT!G36 -> 501 | H36: =TT!H36 -> MATHS-I | I36: =TT!I36 -> 0 | J36: =TT!J36 -> PDB | K36: =TT!K36 -> 502 | ... BC36: =TT!BC36 -> 0
D37: =TT!D37 -> 0 | E37: =TT!E37 -> 0 | F37: =TT!F37 -> 0 | G37: =TT!G37 -> 0 | H37: =TT!H37 -> 0 | I37: =TT!I37 -> 0 | J37: =TT!J37 -> 0 | K37: =TT!K37 -> 0 | ... BC37: =TT!BC37 -> 0
B38: BREAK | C38: 10:45 am to 11:30 am | D38: =TT!D38 -> 0 | E38: =TT!E38 -> 0 | F38: =TT!F38 -> 0 | G38: =TT!G38 -> 0 | H38: =TT!H38 -> 0 | I38: =TT!I38 -> 0 | J38: =TT!J38 -> 0 | K38: =TT!K38 -> 0 | ... BC38: =TT!BC38 -> 0
D39: =TT!D39 -> 0 | E39: =TT!E39 -> 0 | F39: =TT!F39 -> 0 | G39: =TT!G39 -> 0 | H39: =TT!H39 -> 0 | I39: =TT!I39 -> 0 | J39: =TT!J39 -> 0 | K39: =TT!K39 -> 0 | ... BC39: =TT!BC39 -> 0
B40: 3 | C40: 11:30am to 12:30pm | D40: =TT!D40 -> PYTHON-I | E40: =TT!E40 -> 0 | F40: =TT!F40 -> HDS | G40: =TT!G40 -> 506-A | H40: =TT!H40 -> PHY | I40: =TT!I40 -> 0 | J40: =TT!J40 -> PYR | K40: =TT!K40 -> 509 | ... BC40: =TT!BC40 -> 0
...

Sheet TT
A1: L J Institute of Engineering and Technology
A2: FY1 SEM I BATCH 2026 (CE/AIML)
A3: Class Time Table Effective From 31 August 2026
C4: BRANCH
B5: V 1.0 | C5: DIVISION | D5: D-1 | H5: D-2 | L5: D-3 | P5: D-4 | T5: D-5 | X5: D-6 | AB5: D-7 | AF5: D-8 | AJ5: D-9 | AR5: V 1.0 | AV5: DIVISION
D6: C1 | AV6: BATCH-12 | AZ6: BATCH-13
A7: DAY | B7: LECTURE NO | C7: TIME | D7: Subject | E7: Batch | F7: Faculty | G7: Room No | H7: Subject | I7: Batch | J7: Faculty | K7: Room No | L7: Subject | M7: Batch | N7: Faculty | O7: Room No | P7: Subject | Q7: Batch | R7: Faculty | S7: Room No | T7: Subject | U7: Batch | V7: Faculty | W7: Room No | X7: Subject | Y7: Batch | Z7: Faculty | AA7: Room No | AB7: Subject | AC7: Batch | AD7: Faculty | AE7: Room No | AF7: Subject | AG7: Batch | AH7: Faculty | AI7: Room No | AJ7: Subject | AK7: Batch | AL7: Faculty | AM7: Room No | AN7: Subject | AO7: Batch | AP7: Faculty | AQ7: Room No | AR7: Subject | AS7: Batch | AT7: Faculty | AU7: LECTURE NO | AV7: TIME | AW7: DAY
A8: MON | B8: 1 | C8: 8:45am to 9:45am | D8: ES | F8: NND | G8: 501 | H8: ES | J8: NND | K8: 501 | L8: PYTHON-I | N8: JPM | O8: 506-B | P8: PYTHON-I | R8: HDS | S8: 506-C | T8: MATHS-I | V8: AMS | W8: 502 | X8: PYTHON-I | Z8: MDP | AA8: 506-D | AB8: SE | AD8: IRS | AE8: 506-A | AU8: 1 | AV8: 8:45am to 9:45am | AW8: MON
B10: 2 | C10: 9:45 am to 10:45 am | D10: MATHS-I | F10: AMS | G10: 501 | H10: PHY | J10: PYR | K10: 509 | L10: PYTHON-I | N10: JPM | O10: 506-B | P10: PYTHON-I | R10: HDS | S10: 506-C | T10: SE | V10: IRS | W10: 502 | X10: PYTHON-I | Z10: MDP | AA10: 506-D | AB10: PHY | AD10: KGB | AE10: 511 | AU10: 2 | AV10: 9:45 am to 10:45 am
B12: BREAK | C12: 10:45 am to 11:30 am | AU12: BREAK | AV12: 10:45 am to 11:30 am
B14: 3 | C14: 11:30am to 12:30pm | D14: SE | F14: IRS | G14: 506-A | H14: PYTHON-I | J14: MDP | K14: 506-D | L14: PHY | N14: KGB | O14: 502 | P14: MATHS-I | R14: PDB | S14: 501 | T14: PYTHON-I | V14: VVP | W14: 506-C | X14: PHY | Z14: PYR | AA14: 509 | AB14: MATHS-I | AD14: AMS | AE14: 511 | AU14: 3 | AV14: 11:30am to 12:30pm
B16: 4 | C16: 12:30pm to 1:30pm | D16: PHY | F16: KGB | G16: 506-A | H16: PYTHON-I | J16: MDP | K16: 506-D | L16: SE | N16: IRS | O16: 502 | P16: MATHS-I | R16: PDB | S16: 501 | T16: PYTHON-I | V16: VVP | W16: 506-C | X16: PHY | Z16: PYR | AA16: 509 | AB16: MATHS-I | AD16: AMS | AE16: 511 | AU16: 4 | AV16: 12:30pm to 1:30pm
B18: 5 | C18: 1:30pm to 2:30pm | AU18: 5 | AV18: 1:30pm to 2:30pm
A21: TUE | B21: 1 | C21: =$C$8 -> 8:45am to 9:45am | D21: PYTHON-I | F21: HDS | G21: 506-A | H21: PHY | J21: PYR | K21: 509 | L21: PYTHON-I | N21: JPM | O21: 506-B | P21: MATHS-I | R21: PDB | S21: 502 | T21: PHY | V21: KGB | W21: 511 | X21: ES | Z21: NND | AA21: 501 | AB21: ES | AD21: NND | AE21: 501 | AU21: 1 | AV21: =$C$8 -> 8:45am to 9:45am | AW21: TUE
B23: 2 | C23: =$C$10 -> 9:45 am to 10:45 am | D23: PYTHON-I | F23: HDS | G23: 506-A | H23: PHY | J23: PYR | K23: 509 | L23: PYTHON-I | N23: JPM | O23: 506-B | P23: MATHS-I | R23: PDB | S23: 502 | T23: PHY | V23: KGB | W23: 511 | X23: SE | Z23: IRS | AA23: 506-D | AB23: MATHS-I | AD23: AMS | AE23: 501 | AU23: 2 | AV23: =$C$10 -> 9:45 am to 10:45 am
B25: BREAK | C25: =$C$12 -> 10:45 am to 11:30 am | AU25: BREAK | AV25: =$C$12 -> 10:45 am to 11:30 am
B27: 3 | C27: =$C$14 -> 11:30am to 12:30pm | D27: MATHS-I | F27: AMS | G27: 501 | H27: MATHS-I | J27: PDB | K27: 502 | L27: PHY | N27: KGB | O27: 509 | P27: PYTHON-I | R27: HDS | S27: 506-C | T27: SE | V27: IRS | W27: 506-A | X27: PYTHON-I | Z27: MDP | AA27: 506-D | AB27: PYTHON-I | AD27: JPM | AE27: 506-B | AU27: 3 | AV27: =$C$14 -> 11:30am to 12:30pm
B29: 4 | C29: =$C$16 -> 12:30pm to 1:30pm | D29: MATHS-I | F29: AMS | G29: 501 | H29: MATHS-I | J29: PDB | K29: 502 | L29: PHY | N29: KGB | O29: 509 | P29: PYTHON-I | R29: HDS | S29: 506-C | T29: SE | V29: IRS | W29: 506-A | X29: PYTHON-I | Z29: MDP | AA29: 506-D | AB29: PYTHON-I | AD29: JPM | AE29: 506-B | AU29: 4 | AV29: =$C$16 -> 12:30pm to 1:30pm
B31: 5 | C31: =$C$18 -> 1:30pm to 2:30pm | AU31: 5 | AV31: =$C$18 -> 1:30pm to 2:30pm
A34: WED | B34: 1 | C34: =$C$8 -> 8:45am to 9:45am | D34: MATHS-I | F34: AMS | G34: 501 | H34: SE | J34: IRS | K34: 502 | L34: PHY | N34: KGB | O34: 509 | P34: PHY | R34: PYR | S34: 506-D | T34: PYTHON-I | V34: VVP | W34: 506-C | X34: MATHS-I | Z34: PDB | AA34: 511 | AB34: PYTHON-I | AD34: JPM | AE34: 506-B | AU34: 1 | AV34: =$C$8 -> 8:45am to 9:45am | AW34: WED
B36: 2 | C36: =$C$10 -> 9:45 am to 10:45 am | D36: MATHS-I | F36: AMS | G36: 501 | H36: MATHS-I | J36: PDB | K36: 502 | L36: PHY | N36: KGB | O36: 509 | P36: SE | R36: IRS | S36: 506-D | T36: PYTHON-I | V36: VVP | W36: 506-C | X36: PHY | Z36: PYR | AA36: 511 | AB36: PYTHON-I | AD36: JPM | AE36: 506-B | AU36: 2 | AV36: =$C$10 -> 9:45 am to 10:45 am
B38: BREAK | C38: =$C$12 -> 10:45 am to 11:30 am | AU38: BREAK | AV38: =$C$12 -> 10:45 am to 11:30 am
B40: 3 | C40: =$C$14 -> 11:30am to 12:30pm | D40: PYTHON-I | F40: HDS | G40: 506-A | H40: PHY | J40: PYR | K40: 509 | L40: MATHS-I | N40: JVA | O40: 506-B | P40: MATHS-I | R40: PDB | S40: 502 | T40: MATHS-I | V40: AMS | W40: 511 | X40: PYTHON-I | Z40: MDP | AA40: 506-D | AB40: PHY | AD40: KGB | AE40: 501 | AU40: 3 | AV40: =$C$14 -> 11:30am to 12:30pm
B42: 4 | C42: =$C$16 -> 12:30pm to 1:30pm | D42: PYTHON-I | F42: HDS | G42: 506-A | H42: PHY | J42: PYR | K42: 509 | L42: MATHS-I | N42: JVA | O42: 506-B | P42: MATHS-I | R42: PDB | S42: 502 | T42: MATHS-I | V42: AMS | W42: 511 | X42: PYTHON-I | Z42: MDP | AA42: 506-D | AB42: PHY | AD42: KGB | AE42: 501 | AU42: 4 | AV42: =$C$16 -> 12:30pm to 1:30pm
B44: 5 | C44: =$C$18 -> 1:30pm to 2:30pm | AU44: 5 | AV44: =$C$18 -> 1:30pm to 2:30pm
A47: THU | B47: 1 | C47: =$C$8 -> 8:45am to 9:45am | D47: PYTHON-I | F47: HDS | G47: 506-A | H47: SE | J47: IRS | K47: 506-D | L47: MATHS-I | N47: JVA | O47: 506-C | P47: MATHS-I | R47: PDB | S47: 501 | T47: PHY | V47: KGB | W47: 509 | X47: PHY | Z47: PYR | AA47: 502 | AB47: MATHS-I | AD47: AMS | AE47: 511 | AU47: 1 | AV47: =$C$8 -> 8:45am to 9:45am | AW47: THU
B49: 2 | C49: =$C$10 -> 9:45 am to 10:45 am | D49: PYTHON-I | F49: HDS | G49: 506-A | H49: SE | J49: IRS | K49: 506-D | L49: ES | N49: NND | O49: 501 | P49: ES | R49: NND | S49: 501 | T49: PHY | V49: KGB | W49: 509 | X49: PHY | Z49: PYR | AA49: 502 | AB49: MATHS-I | AD49: AMS | AE49: 511 | AU49: 2 | AV49: =$C$10 -> 9:45 am to 10:45 am
B51: BREAK | C51: =$C$12 -> 10:45 am to 11:30 am | AU51: BREAK | AV51: =$C$12 -> 10:45 am to 11:30 am
B53: 3 | C53: =$C$14 -> 11:30am to 12:30pm | D53: PHY | F53: KGB | G53: 509 | H53: PYTHON-I | J53: MDP | K53: 506-D | L53: SE | N53: IRS | O53: 506-A | P53: PYTHON-I | R53: HDS | S53: 506-C | T53: MATHS-I | V53: AMS | W53: 501 | X53: MATHS-I | Z53: PDB | AA53: 502 | AB53: PYTHON-I | AD53: JPM | AE53: 506-B | AU53: 3 | AV53: =$C$14 -> 11:30am to 12:30pm
B55: 4 | C55: =$C$16 -> 12:30pm to 1:30pm | D55: PHY | F55: KGB | G55: 509 | H55: PYTHON-I | J55: MDP | K55: 506-D | L55: SE | N55: IRS | O55: 506-A | P55: PYTHON-I | R55: HDS | S55: 506-C | T55: MATHS-I | V55: AMS | W55: 501 | X55: MATHS-I | Z55: PDB | AA55: 502 | AB55: PYTHON-I | AD55: JPM | AE55: 506-B | AU55: 4 | AV55: =$C$16 -> 12:30pm to 1:30pm
B57: 5 | C57: =$C$18 -> 1:30pm to 2:30pm | AU57: 5 | AV57: =$C$18 -> 1:30pm to 2:30pm
A60: FRI | B60: 1 | C60: =$C$8 -> 8:45am to 9:45am | D60: PHY | F60: KGB | G60: 511 | H60: MATHS-I | J60: PDB | K60: 501 | L60: MATHS-I | N60: JVA | O60: 502 | P60: PHY | R60: PYR | S60: 509 | T60: MATHS-I | V60: AMS | W60: 506-A | X60: PYTHON-I | Z60: MDP | AA60: 506-D | AB60: SE | AD60: IRS | AE60: 506-B | AU60: 1 | AV60: =$C$8 -> 8:45am to 9:45am | AW60: FRI
B62: 2 | C62: =$C$10 -> 9:45 am to 10:45 am | D62: PHY | F62: KGB | G62: 511 | H62: MATHS-I | J62: PDB | K62: 501 | L62: MATHS-I | N62: JVA | O62: 502 | P62: PHY | R62: PYR | S62: 509 | T62: MATHS-I | V62: AMS | W62: 506-A | X62: PYTHON-I | Z62: MDP | AA62: 506-D | AB62: SE | AD62: IRS | AE62: 506-B | AU62: 2 | AV62: =$C$10 -> 9:45 am to 10:45 am
B64: BREAK | C64: =$C$12 -> 10:45 am to 11:30 am | AU64: BREAK | AV64: =$C$12 -> 10:45 am to 11:30 am
B66: 3 | C66: =$C$14 -> 11:30am to 12:30pm | D66: SE | F66: IRS | G66: 511 | H66: PYTHON-I | J66: MDP | K66: 506-D | L66: PYTHON-I | N66: JPM | O66: 506-B | P66: PYTHON-I | R66: HDS | S66: 506-C | T66: PYTHON-I | V66: VVP | W66: 506-A | X66: MATHS-I | Z66: PDB | AA66: 501 | AB66: MATHS-I | AD66: AMS | AE66: 502 | AU66: 3 | AV66: =$C$14 -> 11:30am to 12:30pm
B68: 4 | C68: =$C$16 -> 12:30pm to 1:30pm | D68: SE | F68: IRS | G68: 511 | H68: PYTHON-I | J68: MDP | K68: 506-D | L68: PYTHON-I | N68: JPM | O68: 506-B | P68: PYTHON-I | R68: HDS | S68: 506-C | T68: PYTHON-I | V68: VVP | W68: 506-A | X68: MATHS-I | Z68: PDB | AA68: 501 | AB68: MATHS-I | AD68: AMS | AE68: 502 | AU68: 4 | AV68: =$C$16 -> 12:30pm to 1:30pm
B70: 5 | C70: =$C$18 -> 1:30pm to 2:30pm | AU70: 5 | AV70: =$C$18 -> 1:30pm to 2:30pm
A73: SAT | B73: 1 | C73: =$C$8 -> 8:45am to 9:45am | D73: PYTHON-I | F73: HDS | G73: 506-A | H73: PYTHON-I | J73: MDP | K73: 506-D | L73: PYTHON-I | N73: JPM | O73: 506-B | P73: SE | R73: IRS | S73: 502 | T73: PYTHON-I | V73: VVP | W73: 506-C | X73: MATHS-I | Z73: PDB | AA73: 501 | AB73: PHY | AD73: KGB | AE73: 509 | AU73: 1 | AV73: =$C$8 -> 8:45am to 9:45am | AW73: SAT
B75: 2 | C75: =$C$10 -> 9:45 am to 10:45 am | D75: PYTHON-I | F75: HDS | G75: 506-A | H75: PYTHON-I | J75: MDP | K75: 506-D | L75: PYTHON-I | N75: JPM | O75: 506-B | P75: SE | R75: IRS | S75: 502 | T75: PYTHON-I | V75: VVP | W75: 506-C | X75: MATHS-I | Z75: PDB | AA75: 501 | AB75: PHY | AD75: KGB | AE75: 509 | AU75: 2 | AV75: =$C$10 -> 9:45 am to 10:45 am
B77: BREAK | C77: =$C$12 -> 10:45 am to 11:30 am | AU77: BREAK | AV77: =$C$12 -> 10:45 am to 11:30 am
...

Sheet Faculty TT
A1: L J Institute of Engineering and Technology
A2: FY1 SEM I BATCH 2026 (CE/AIML)
A3: =TT!A3 -> Class Time Table Effective From 31 August 2026
B4: =TT!B5 -> V 1.0 | C4: FACULTY - SUBJECTS | D4: 1 | H4: 2 | J4: MATHS-I | L4: 3 | N4: MATHS-I | P4: 4 | R4: PHY | T4: 5 | V4: PHY | X4: 6 | Z4: PYTHON-I | AB4: 7 | AD4: PYTHON-I | AJ4: 8 | AL4: PYTHON-I | AN4: 9 | AP4: SE | AR4: 10 | AT4: ES | AV4: 11 | AX4: PYTHON-I | AY4: VISITING | AZ4: 12 | BB4: MATHS-I | BC4: VISITING | BD4: 13 | BH4: 13 | BL4: 15 | BN4: SE | BO4: VF | BP4: 16 | BR4: ES | BS4: VF | BT4: 17 | BV4: ES | BW4: VF | BX4: 19 | BZ4: ADMIN | CB4: 20 | CC4: 20 | CE4: MATHS | CF4: 21 | CI4: MATHS | CJ4: 22 | CM4: MATHS | CN4: 23 | CO4: 20 | CP4: VISITING | CQ4: MATHS | CR4: 24 | CT4: VISITING | CU4: JAVA | CV4: 25 | CX4: VISITING | CZ4: 23 | DD4: FACULTY - SUBJECTS
A5: DAY | B5: Lect No | C5: Faculty Initials --> | D5: ZAB | H5: AMS | L5: PDB | P5: KGB | T5: PYR | X5: JPM | AB5: HDS | AJ5: MDP | AN5: IRS | AR5: NND | AV5: VVP | AZ5: JVA | BD5: VRS | BH5: VSA | BL5: HPP | BP5: UPR | BT5: VSA | BX5: PVS | CB5: EXTRA | CF5: EXTRA | CJ5: EXTRA | CN5: EXTRA | CR5: EXTRA | CV5: EXTRA | CZ5: EXTRA | DD5: Faculty Initials --> | DE5: DAY
C6: TIME | DD6: TIME
C7: TIME | D7: Subject | E7: Batch | F7: Faculty | G7: Room No | H7: Subject | I7: Batch | J7: Faculty | K7: Room No | L7: Subject | M7: Batch | N7: Faculty | O7: Room No | P7: Subject | Q7: Batch | R7: Faculty | S7: Room No | T7: Subject | U7: Batch | V7: Faculty | W7: Room No | X7: Subject | Y7: Batch | Z7: Faculty | AA7: Room No | AB7: Subject | AC7: Batch | AD7: Faculty | AE7: Room No | AF7: Subject | AG7: Batch | AH7: Faculty | AI7: Room No | AJ7: Subject | AK7: Batch | AL7: Faculty | AM7: Room No | AN7: Subject | AO7: Batch | AP7: Faculty | AQ7: Room No | AR7: Subject | AS7: Batch | AT7: Faculty | AU7: Room No | AV7: Subject | AW7: Batch | AX7: Faculty | AY7: Room No | AZ7: Subject | BA7: Batch | BB7: Faculty | BC7: Room No | BD7: Subject | BE7: Batch | BF7: Faculty | BG7: Room No | BH7: Subject | BI7: Batch | BJ7: Faculty | BK7: Room No | BL7: Subject | BM7: Batch | BN7: Faculty | BO7: Room No | BP7: Subject | BQ7: Batch | BR7: Faculty | BS7: Room No | BT7: Subject | BU7: Batch | BV7: Faculty | BW7: Room No | BX7: Subject | BY7: Batch | BZ7: Faculty | CA7: Room No | CB7: Subject | CC7: Batch | CD7: Faculty | CE7: Room No | CF7: Subject | CG7: Batch | CH7: Faculty | CI7: Room No | CJ7: Subject | CK7: Batch | CL7: Faculty | CM7: Room No | CN7: Subject | CO7: Batch | CP7: Faculty | CQ7: Room No | CR7: Subject | CS7: Batch | CT7: Faculty | CU7: Room No | CV7: Subject | CW7: Batch | CX7: Faculty | CY7: Room No | CZ7: Subject | DA7: Batch | DB7: Faculty | DC7: Room No | DD7: TIME
